ERROR:root:Exception occured
Traceback (most recent call last):
  File "main.py", line 33, in catchErrors
    self.executePythonFile()
  File "main.py", line 24, in executePythonFile
    exec(open(arg).read())
  File "<string>", line 14, in <module>
  File "<string>", line 6, in foo
IndexError: list index out of range
ERROR:root:Exception occured
Traceback (most recent call last):
  File "main.py", line 34, in catchErrors
    self.executePythonFile()
  File "main.py", line 25, in executePythonFile
    exec(open(arg).read())
  File "<string>", line 14, in <module>
  File "<string>", line 6, in foo
IndexError: list index out of range
ERROR:root:Exception occured
Traceback (most recent call last):
  File "/Users/oscargandara/overflow/main.py", line 34, in catchErrors
    self.executePythonFile()
  File "/Users/oscargandara/overflow/main.py", line 23, in executePythonFile
    inFile = sys.argv[1]
IndexError: list index out of range
ERROR:root:Exception occured
Traceback (most recent call last):
  File "main.py", line 34, in catchErrors
    self.executePythonFile()
  File "main.py", line 25, in executePythonFile
    exec(open(arg).read())
  File "<string>", line 14, in <module>
  File "<string>", line 6, in foo
IndexError: list index out of range
ERROR:root:Exception occured
Traceback (most recent call last):
  File "main.py", line 34, in catchErrors
    self.executePythonFile()
  File "main.py", line 25, in executePythonFile
    exec(open(arg).read())
  File "<string>", line 14, in <module>
  File "<string>", line 6, in foo
IndexError: list index out of range
ERROR:root:Exception occured
Traceback (most recent call last):
  File "main.py", line 34, in catchErrors
    self.executePythonFile()
  File "main.py", line 25, in executePythonFile
    exec(open(arg).read())
  File "<string>", line 14, in <module>
  File "<string>", line 6, in foo
IndexError: list index out of range
ERROR:root:Exception occured
Traceback (most recent call last):
  File "main.py", line 34, in catchErrors
    self.executePythonFile()
  File "main.py", line 25, in executePythonFile
    exec(open(arg).read())
  File "<string>", line 14, in <module>
  File "<string>", line 6, in foo
IndexError: list index out of range
ERROR:root:Exception occured
Traceback (most recent call last):
  File "main.py", line 34, in catchErrors
    self.executePythonFile()
  File "main.py", line 25, in executePythonFile
    exec(open(arg).read())
  File "<string>", line 14, in <module>
  File "<string>", line 6, in foo
IndexError: list index out of range
ERROR:root:Exception occured
Traceback (most recent call last):
  File "main.py", line 34, in catchErrors
    self.executePythonFile()
  File "main.py", line 25, in executePythonFile
    exec(open(arg).read())
  File "<string>", line 14, in <module>
  File "<string>", line 6, in foo
IndexError: list index out of range
ERROR:root:Exception occured
Traceback (most recent call last):
  File "main.py", line 34, in catchErrors
    self.executePythonFile()
  File "main.py", line 25, in executePythonFile
    exec(open(arg).read())
  File "<string>", line 14, in <module>
  File "<string>", line 6, in foo
IndexError: list index out of range
ERROR:root:Exception occured
Traceback (most recent call last):
  File "main.py", line 34, in catchErrors
    self.executePythonFile()
  File "main.py", line 25, in executePythonFile
    exec(open(arg).read())
  File "<string>", line 14, in <module>
  File "<string>", line 6, in foo
IndexError: list index out of range
ERROR:root:Exception occured
Traceback (most recent call last):
  File "main.py", line 34, in catchErrors
    self.executePythonFile()
  File "main.py", line 25, in executePythonFile
    exec(open(arg).read())
  File "<string>", line 14, in <module>
  File "<string>", line 6, in foo
IndexError: list index out of range
ERROR:root:Exception occured
Traceback (most recent call last):
  File "main.py", line 34, in catchErrors
    self.executePythonFile()
  File "main.py", line 25, in executePythonFile
    exec(open(arg).read())
  File "<string>", line 14, in <module>
  File "<string>", line 6, in foo
IndexError: list index out of range
ERROR:root:Exception occured
Traceback (most recent call last):
  File "main.py", line 34, in catchErrors
    self.executePythonFile()
  File "main.py", line 25, in executePythonFile
    exec(open(arg).read())
  File "<string>", line 14, in <module>
  File "<string>", line 6, in foo
IndexError: list index out of range
ERROR:root:Exception occured
Traceback (most recent call last):
  File "main.py", line 34, in catchErrors
    self.executePythonFile()
  File "main.py", line 25, in executePythonFile
    exec(open(arg).read())
  File "<string>", line 14, in <module>
  File "<string>", line 6, in foo
IndexError: list index out of range
ERROR:root:Exception occured
Traceback (most recent call last):
  File "main.py", line 34, in catchErrors
    self.executePythonFile()
  File "main.py", line 25, in executePythonFile
    exec(open(arg).read())
  File "<string>", line 14, in <module>
  File "<string>", line 6, in foo
IndexError: list index out of range
ERROR:root:Exception occured
Traceback (most recent call last):
  File "main.py", line 34, in catchErrors
    self.executePythonFile()
  File "main.py", line 25, in executePythonFile
    exec(open(arg).read())
  File "<string>", line 14, in <module>
  File "<string>", line 6, in foo
IndexError: list index out of range
ERROR:root:Exception occured
Traceback (most recent call last):
  File "main.py", line 34, in catchErrors
    self.executePythonFile()
  File "main.py", line 25, in executePythonFile
    exec(open(arg).read())
  File "<string>", line 14, in <module>
  File "<string>", line 6, in foo
IndexError: list index out of range
ERROR:root:Exception occured
Traceback (most recent call last):
  File "main.py", line 34, in catchErrors
    self.executePythonFile()
  File "main.py", line 25, in executePythonFile
    exec(open(arg).read())
  File "<string>", line 14, in <module>
  File "<string>", line 6, in foo
IndexError: list index out of range
ERROR:root:Exception occured
Traceback (most recent call last):
  File "main.py", line 34, in catchErrors
    self.executePythonFile()
  File "main.py", line 25, in executePythonFile
    exec(open(arg).read())
  File "<string>", line 14, in <module>
  File "<string>", line 6, in foo
IndexError: list index out of range
ERROR:root:Exception occured
Traceback (most recent call last):
  File "main.py", line 34, in catchErrors
    self.executePythonFile()
  File "main.py", line 25, in executePythonFile
    exec(open(arg).read())
  File "<string>", line 14, in <module>
  File "<string>", line 6, in foo
IndexError: list index out of range
ERROR:root:Exception occured
Traceback (most recent call last):
  File "main.py", line 34, in catchErrors
    self.executePythonFile()
  File "main.py", line 25, in executePythonFile
    exec(open(arg).read())
  File "<string>", line 14, in <module>
  File "<string>", line 6, in foo
IndexError: list index out of range
ERROR:root:Exception occured
Traceback (most recent call last):
  File "/Users/oscargandara/overflow/Main.py", line 34, in catchErrors
    self.executePythonFile()
  File "/Users/oscargandara/overflow/Main.py", line 25, in executePythonFile
    exec(open(arg).read())
FileNotFoundError: [Errno 2] No such file or directory: './/Users/oscargandara/overflow/error.py'
ERROR:root:Exception occured
Traceback (most recent call last):
  File "main.py", line 34, in catchErrors
    self.executePythonFile()
  File "main.py", line 25, in executePythonFile
    exec(open(arg).read())
  File "<string>", line 14, in <module>
  File "<string>", line 6, in foo
IndexError: list index out of range
ERROR:root:Exception occured
Traceback (most recent call last):
  File "main.py", line 34, in catchErrors
    self.executePythonFile()
  File "main.py", line 25, in executePythonFile
    exec(open(arg).read())
  File "<string>", line 14, in <module>
  File "<string>", line 6, in foo
IndexError: list index out of range
ERROR:root:Exception occured
Traceback (most recent call last):
  File "main.py", line 34, in catchErrors
    self.executePythonFile()
  File "main.py", line 25, in executePythonFile
    exec(open(arg).read())
  File "<string>", line 14, in <module>
  File "<string>", line 6, in foo
IndexError: list index out of range
ERROR:root:Exception occured
Traceback (most recent call last):
  File "main.py", line 34, in catchErrors
    self.executePythonFile()
  File "main.py", line 25, in executePythonFile
    exec(open(arg).read())
  File "<string>", line 14, in <module>
  File "<string>", line 6, in foo
IndexError: list index out of range
ERROR:root:Exception occured
Traceback (most recent call last):
  File "main.py", line 34, in catchErrors
    self.executePythonFile()
  File "main.py", line 25, in executePythonFile
    exec(open(arg).read())
  File "<string>", line 14, in <module>
  File "<string>", line 6, in foo
IndexError: list index out of range
ERROR:root:Exception occured
Traceback (most recent call last):
  File "main.py", line 34, in catchErrors
    self.executePythonFile()
  File "main.py", line 25, in executePythonFile
    exec(open(arg).read())
  File "<string>", line 14, in <module>
  File "<string>", line 6, in foo
IndexError: list index out of range
ERROR:root:Exception occured
Traceback (most recent call last):
  File "main.py", line 34, in catchErrors
    self.executePythonFile()
  File "main.py", line 25, in executePythonFile
    exec(open(arg).read())
  File "<string>", line 14, in <module>
  File "<string>", line 6, in foo
IndexError: list index out of range
ERROR:root:Exception occured
Traceback (most recent call last):
  File "main.py", line 34, in catchErrors
    self.executePythonFile()
  File "main.py", line 25, in executePythonFile
    exec(open(arg).read())
  File "<string>", line 14, in <module>
  File "<string>", line 6, in foo
IndexError: list index out of range
ERROR:root:Exception occured
Traceback (most recent call last):
  File "main.py", line 34, in catchErrors
    self.executePythonFile()
  File "main.py", line 25, in executePythonFile
    exec(open(arg).read())
  File "<string>", line 14, in <module>
  File "<string>", line 6, in foo
IndexError: list index out of range
ERROR:root:Exception occured
Traceback (most recent call last):
  File "main.py", line 34, in catchErrors
    self.executePythonFile()
  File "main.py", line 25, in executePythonFile
    exec(open(arg).read())
  File "<string>", line 14, in <module>
  File "<string>", line 6, in foo
IndexError: list index out of range
ERROR:root:Exception occured
Traceback (most recent call last):
  File "main.py", line 34, in catchErrors
    self.executePythonFile()
  File "main.py", line 25, in executePythonFile
    exec(open(arg).read())
  File "<string>", line 14, in <module>
  File "<string>", line 6, in foo
IndexError: list index out of range
ERROR:root:Exception occured
Traceback (most recent call last):
  File "main.py", line 34, in catchErrors
    self.executePythonFile()
  File "main.py", line 25, in executePythonFile
    exec(open(arg).read())
  File "<string>", line 14, in <module>
  File "<string>", line 6, in foo
IndexError: list index out of range
ERROR:root:Exception occured
Traceback (most recent call last):
  File "main.py", line 34, in catchErrors
    self.executePythonFile()
  File "main.py", line 25, in executePythonFile
    exec(open(arg).read())
  File "<string>", line 14, in <module>
  File "<string>", line 6, in foo
IndexError: list index out of range
ERROR:root:Exception occured
Traceback (most recent call last):
  File "main.py", line 34, in catchErrors
    self.executePythonFile()
  File "main.py", line 25, in executePythonFile
    exec(open(arg).read())
  File "<string>", line 14, in <module>
  File "<string>", line 6, in foo
IndexError: list index out of range
ERROR:root:Exception occured
Traceback (most recent call last):
  File "/Users/oscargandara/overflow/main.py", line 34, in catchErrors
    self.executePythonFile()
  File "/Users/oscargandara/overflow/main.py", line 23, in executePythonFile
    inFile = sys.argv[1]
IndexError: list index out of range
ERROR:root:Exception occured
Traceback (most recent call last):
  File "/Users/oscargandara/overflow/main.py", line 34, in catchErrors
    self.executePythonFile()
  File "/Users/oscargandara/overflow/main.py", line 23, in executePythonFile
    inFile = sys.argv[1]
IndexError: list index out of range
ERROR:root:Exception occured
Traceback (most recent call last):
  File "main.py", line 34, in catchErrors
    self.executePythonFile()
  File "main.py", line 25, in executePythonFile
    exec(open(arg).read())
  File "<string>", line 14, in <module>
  File "<string>", line 6, in foo
IndexError: list index out of range
